<?xml version="1.0" ?>
<robot name="robot_model">
    <material name="material_0">
        <color rgba="1.0 1.0 1.0 1.0" />
        <texture filename="wood_0.png" />
    </material>
    <link name="base_link">
        <visual>
            <geometry>
                <box size="0.25 0.125 0.15" />
            </geometry>
            <origin rpy="0 0 0" xyz="0 0 0" />
            <material name="material_0" />
        </visual>
        <collision>
            <geometry>
                <box size="0.25 0.125 0.15" />
            </geometry>
            <origin rpy="0 0 0" xyz="0 0 0" />
        </collision>
        <inertial>
            <origin rpy="0 -0 0" xyz="0 0 0" />
            <mass value="5" />
            <inertia xx="1" xy="0" xz="0" yy="1" yz="0" zz="1" />
        </inertial>
    </link>
    <link name="node_0_link">
        <visual>
            <geometry>
                <cylinder length="0.5" radius="0.05" />
                <newton replaceWith="capsule" />
            </geometry>
            <origin rpy="-0 0 0" xyz="0 0 0.25" />
            <material name="material_0" />
        </visual>
        <collision>
            <geometry>
                <cylinder length="0.5" radius="0.05" />
                <newton replaceWith="capsule" />
            </geometry>
            <origin rpy="-0 0 0" xyz="0 0 0.25" />
        </collision>
        <inertial>
            <origin rpy="0 -0 0" xyz="0 0 0" />
            <mass value="10" />
            <inertia xx="1" xy="0" xz="0" yy="1" yz="0" zz="1" />
        </inertial>
    </link>
    <joint name="node_0_link_to_base_link" type="continuous">
        <parent link="base_link" />
        <child link="node_0_link" />
        <origin rpy="0 0 1.57075" xyz="0 0 0" />
    </joint>
</robot>
