<?xml version="1.0" ?>
<robot name="robot_model">
    <material name="material_0">
        <color rgba="1.0 1.0 1.0 1.0" />
        <texture filename="wood_0.png" />
    </material>
    <link name="base_link">
        <visual>
            <geometry>
                <box size="0.703125 0.9375 0.585938" />
            </geometry>
            <origin rpy="1.5708 1.50996e-07 1.5708" xyz="0 0 0" />
            <material name="material_0" />
        </visual>
        <collision>
            <geometry>
                <box size="0.703125 0.9375 0.585938" />
            </geometry>
            <origin rpy="1.5708 1.50996e-07 1.5708" xyz="0 0 0" />
        </collision>
        <inertial>
            <origin rpy="0 -0 0" xyz="1.92697e-10 -1.02746e-09 8.43e-10" />
            <mass value="20" />
            <inertia xx="2.28882" xy="0" xz="0" yy="1.39618" yz="0" zz="2.03705" />
        </inertial>
    </link>
    <link name="leg">
        <visual>
            <geometry>
                <box size="0.1 0.1 0.1" />
            </geometry>
            <origin rpy="3.14965e-13 -4.26084e-07 4.54745e-13" xyz="-0.351311 -4.47035e-07 -1.34332e-07" />
            <material name="material_0" />
        </visual>
        <collision>
            <geometry>
                <box size="0.1 0.1 0.1" />
            </geometry>
            <origin rpy="3.14965e-13 -4.26084e-07 4.54745e-13" xyz="-0.351311 -4.47035e-07 -1.34332e-07" />
        </collision>
        <inertial>
            <origin rpy="0 -0 0" xyz="0.00105192 0.927827 4.15052e-06" />
            <mass value="1" />
            <inertia xx="1.19022" xy="-7.41984e-07" xz="8.73548e-13" yy="1.14245" yz="-1.56468e-06" zz="0.0486742" />
        </inertial>
    </link>
    <joint name="leg_to_base_link" type="continuous">
        <parent link="base_link" />
        <child link="leg" />
        <origin rpy="-1.5708 -1.43052e-06 -1.5708" xyz="1.24939e-08 4.31586e-08 0.285827" />
    </joint>
    <link name="wheel">
        <visual>
            <geometry>
                <sphere radius="0.3" />
            </geometry>
            <origin rpy="-6.72651e-14 -1.5708 0" xyz="0 0 0" />
            <material name="material_0" />
        </visual>
        <collision>
            <geometry>
                <sphere radius="0.3" />
            </geometry>
            <origin rpy="-6.72651e-14 -1.5708 0" xyz="0 0 0" />
        </collision>
        <inertial>
            <origin rpy="0 -0 0" xyz="-2.00343e-08 -1.13046e-14 -1.06618e-09" />
            <mass value="5" />
            <inertia xx="0.177212" xy="-1.13261e-07" xz="7.82985e-14" yy="0.177212" yz="-7.25245e-14" zz="0.177212" />
        </inertial>
    </link>
    <joint name="wheel_to_leg" type="continuous">
        <parent link="leg" />
        <child link="wheel" />
        <origin rpy="1.38046e-13 6.39126e-07 -3.14159" xyz="-1.57073e-06 1.82075 -9.48105e-09" />
    </joint>
</robot>
