<?xml version="1.0" ?>
<robot name="robot_model">
    <material name="material_0">
        <color rgba="1.0 1.0 1.0 1.0" />
    </material>
    <link name="base_link">
        <visual>
            <geometry>
                <box size="0.25 0.125 0.15" />
            </geometry>
            <origin rpy="1.5708 -0 0" xyz="0 0 0" />
            <material name="material_0" />
        </visual>
        <collision>
            <geometry>
                <box size="0.25 0.125 0.15" />
            </geometry>
            <origin rpy="1.5708 -0 0" xyz="0 0 0" />
        </collision>
        <inertial>
            <origin rpy="0 -0 0" xyz="0 0 0" />
            <mass value="5" />
            <inertia xx="0.0158854" xy="0" xz="0" yy="0.0325521" yz="8.99239e-10" zz="0.0354167" />
        </inertial>
    </link>
    <link name="node_0_link">
        <visual>
            <geometry>
                <cylinder length="0.46" radius="0.03" />
            </geometry>
            <origin rpy="1.5708 -3.13916e-07 -1.5708" xyz="-0.2 0 0" />
            <material name="material_0" />
        </visual>
        <collision>
            <geometry>
                <cylinder length="0.46" radius="0.03" />
            </geometry>
            <origin rpy="1.5708 -3.13916e-07 -1.5708" xyz="-0.2 0 0" />
        </collision>
        <inertial>
            <origin rpy="0 -0 0" xyz="4.27628e-09 6.37708e-10 1.2479e-10" />
            <mass value="10" />
            <inertia xx="0.00430032" xy="0" xz="0" yy="0.162159" yz="0" zz="0.162159" />
        </inertial>
    </link>
    <joint name="node_0_link_to_base_link" type="continuous">
        <parent link="base_link" />
        <child link="node_0_link" />
        <axis xyz="3.13916e-07 1 -3.13916e-07" />
        <origin rpy="6.27833e-07 1.5708 0" xyz="0 0 0" />
    </joint>
</robot>
