<?xml version="1.0" ?>
<robot name="robot_model">
    <material name="material_0">
        <color rgba="1.0 1.0 1.0 1.0" />
        <texture filename="wood_0.png" />
    </material>
    <link name="base_link">
        <visual>
            <geometry>
                <box size="0.25 0.4 0.3" />
            </geometry>
            <origin rpy="1.5708 -0 0" xyz="0 0 0" />
            <material name="material_0" />
        </visual>
        <collision>
            <geometry>
                <box size="0.25 0.4 0.3" />
            </geometry>
            <origin rpy="1.5708 -0 0" xyz="0 0 0" />
        </collision>
        <inertial>
            <origin rpy="0 -0 0" xyz="0 0 0" />
            <mass value="20" />
            <inertia xx="0.416667" xy="0" xz="0" yy="0.254167" yz="0" zz="0.370833" />
        </inertial>
    </link>
    <link name="node_1_link">
        <visual>
            <geometry>
                <cylinder length="0.35" radius="0.025" />
                <newton replaceWith="capsule" />
            </geometry>
            <origin rpy="0 -0 -8.43876e-22" xyz="-2.26494e-08 -2.26494e-08 0.15" />
            <material name="material_0" />
        </visual>
        <collision>
            <geometry>
                <cylinder length="0.35" radius="0.025" />
                <newton replaceWith="capsule" />
            </geometry>
            <origin rpy="0 -0 -8.43876e-22" xyz="-2.26494e-08 -2.26494e-08 0.15" />
        </collision>
        <inertial>
            <origin rpy="0 -0 0" xyz="-2.37759e-08 -2.24479e-08 0.15" />
            <mass value="1" />
            <inertia xx="0.00932827" xy="2.05887e-16" xz="-2.06427e-17" yy="0.000298036" yz="2.72705e-09" zz="0.00932827" />
        </inertial>
    </link>
    <joint name="node_1_link_to_base_link" type="continuous">
        <parent link="base_link" />
        <child link="node_1_link" />
        <origin rpy="3.14159 -3.01992e-07 -1.5708" xyz="0 -3.01992e-08 -0.2" />
    </joint>
    <link name="node_0_link">
        <visual>
            <geometry>
                <sphere radius="0.1" />
            </geometry>
            <origin rpy="8.43876e-22 1.5708 0" xyz="0 0 0" />
            <material name="material_0" />
        </visual>
        <collision>
            <geometry>
                <sphere radius="0.1" />
            </geometry>
            <origin rpy="8.43876e-22 1.5708 0" xyz="0 0 0" />
        </collision>
        <inertial>
            <origin rpy="0 -0 0" xyz="0 0 -0" />
            <mass value="1" />
            <inertia xx="0.004" xy="-3.40679e-24" xz="-1.35008e-17" yy="0.004" yz="-2.70016e-17" zz="0.004" />
        </inertial>
    </link>
    <joint name="node_0_link_to_node_1_link" type="continuous">
        <parent link="node_1_link" />
        <child link="node_0_link" />
        <origin rpy="0 -0 -1.68775e-21" xyz="-4.52987e-08 -4.52987e-08 0.3" />
    </joint>
</robot>
